Workbook
Name HIGH: stockdata!$L:$L
Name LOW: stockdata!$M:$M
Name OPEN: stockdata!$K:$K
Name PREV.CLOSE: stockdata!$N:$N
Name Slicer_Name: #N/A
Name Slicer_Sector: #N/A
Name Slicer_Year: #N/A

Sheet stockdata
A1: DATE | B1: StockID | C1: Month | D1: Month Number | E1: Year | F1: QuaterR | G1: Quarter | H1: Stocks | I1: Sector | J1: SERIES | K1: OPEN | L1: HIGH | M1: LOW | N1: PREV. CLOSE | O1: LTP | P1: CLOSE | Q1: VWAP | R1: VOLUME | S1: VALUE | T1: NO OF TRADES | U1: DELIVERY QTY | V1: DELIVERY % | W1: Daily Price Change | X1: Daily Return % | Y1: Gain or Loss
A2: 45292 | B2: STCK-2100 | C2: Jan | D2: =MONTH(StockData[[#This Row],[DATE]]) -> 1 | E2: 2024 | F2: Q1 | G2: ="Q"&ROUNDUP(StockData[[#This Row],[Month Number]]/3,0) -> Q1 | H2: AXIS BANK | I2: Banking | J2: EQ | K2: 1095 | L2: 1104 | M2: 1093 | N2: 1102.3 | O2: 1095 | P2: 1097.7 | Q2: 1099.75 | R2: 4083732 | S2: 4.491103e+09 | T2: 160126 | U2: 2258877 | V2: 55.31 | W2: =StockData[[#This Row],[CLOSE]]-StockData[[#This Row],[PREV. CLOSE]] -> -4.6 | X2: =IFERROR((StockData[[#This Row],[CLOSE]]-StockData[[#This Row],[PREV. CLOSE]])/StockData[[#This Row],[PREV. CLOSE]],0) -> -0.0041730926 | Y2: =IF(StockData[[#This Row],[Daily Return %]]>0,"Gain",IF(StockData[[#This Row],[Daily Return %]]<0,"Loss","No Change")) -> Loss
A3: 45293 | B3: STCK-2101 | C3: Jan | D3: =MONTH(StockData[[#This Row],[DATE]]) -> 1 | E3: 2024 | F3: Q1 | G3: ="Q"&ROUNDUP(StockData[[#This Row],[Month Number]]/3,0) -> Q1 | H3: AXIS BANK | I3: Banking | J3: EQ | K3: 1095.1 | L3: 1099.35 | M3: 1082.3 | N3: 1097.7 | O3: 1089.25 | P3: 1093.25 | Q3: 1091.41 | R3: 7895577 | S3: 8.6173459e+09 | T3: 187704 | U3: 4495327 | V3: 56.93 | W3: =StockData[[#This Row],[CLOSE]]-StockData[[#This Row],[PREV. CLOSE]] -> -4.45 | X3: =IFERROR((StockData[[#This Row],[CLOSE]]-StockData[[#This Row],[PREV. CLOSE]])/StockData[[#This Row],[PREV. CLOSE]],0) -> -0.0040539309 | Y3: =IF(StockData[[#This Row],[Daily Return %]]>0,"Gain",IF(StockData[[#This Row],[Daily Return %]]<0,"Loss","No Change")) -> Loss
A4: 45294 | B4: STCK-2102 | C4: Jan | D4: =MONTH(StockData[[#This Row],[DATE]]) -> 1 | E4: 2024 | F4: Q1 | G4: ="Q"&ROUNDUP(StockData[[#This Row],[Month Number]]/3,0) -> Q1 | H4: AXIS BANK | I4: Banking | J4: EQ | K4: 1091 | L4: 1102.6 | M4: 1081.3 | N4: 1093.25 | O4: 1098 | P4: 1098.6 | Q4: 1093.81 | R4: 10225290 | S4: 1.1184475e+10 | T4: 232835 | U4: 5891206 | V4: 57.61 | W4: =StockData[[#This Row],[CLOSE]]-StockData[[#This Row],[PREV. CLOSE]] -> 5.35 | X4: =IFERROR((StockData[[#This Row],[CLOSE]]-StockData[[#This Row],[PREV. CLOSE]])/StockData[[#This Row],[PREV. CLOSE]],0) -> 0.0048936657 | Y4: =IF(StockData[[#This Row],[Daily Return %]]>0,"Gain",IF(StockData[[#This Row],[Daily Return %]]<0,"Loss","No Change")) -> Gain
A5: 45295 | B5: STCK-2103 | C5: Jan | D5: =MONTH(StockData[[#This Row],[DATE]]) -> 1 | E5: 2024 | F5: Q1 | G5: ="Q"&ROUNDUP(StockData[[#This Row],[Month Number]]/3,0) -> Q1 | H5: AXIS BANK | I5: Banking | J5: EQ | K5: 1103 | L5: 1130 | M5: 1100.05 | N5: 1098.6 | O5: 1125 | P5: 1123.4 | Q5: 1120.15 | R5: 11411683 | S5: 1.2782778e+10 | T5: 179554 | U5: 7854267 | V5: 68.83 | W5: =StockData[[#This Row],[CLOSE]]-StockData[[#This Row],[PREV. CLOSE]] -> 24.8 | X5: =IFERROR((StockData[[#This Row],[CLOSE]]-StockData[[#This Row],[PREV. CLOSE]])/StockData[[#This Row],[PREV. CLOSE]],0) -> 0.022574185 | Y5: =IF(StockData[[#This Row],[Daily Return %]]>0,"Gain",IF(StockData[[#This Row],[Daily Return %]]<0,"Loss","No Change")) -> Gain
A6: 45296 | B6: STCK-2104 | C6: Jan | D6: =MONTH(StockData[[#This Row],[DATE]]) -> 1 | E6: 2024 | F6: Q1 | G6: ="Q"&ROUNDUP(StockData[[#This Row],[Month Number]]/3,0) -> Q1 | H6: AXIS BANK | I6: Banking | J6: EQ | K6: 1124 | L6: 1139.9 | M6: 1119 | N6: 1123.4 | O6: 1134.3 | P6: 1136.95 | Q6: 1131.22 | R6: 8025466 | S6: 9.0785623e+09 | T6: 193046 | U6: 5273965 | V6: 65.72 | W6: =StockData[[#This Row],[CLOSE]]-StockData[[#This Row],[PREV. CLOSE]] -> 13.55 | X6: =IFERROR((StockData[[#This Row],[CLOSE]]-StockData[[#This Row],[PREV. CLOSE]])/StockData[[#This Row],[PREV. CLOSE]],0) -> 0.012061599 | Y6: =IF(StockData[[#This Row],[Daily Return %]]>0,"Gain",IF(StockData[[#This Row],[Daily Return %]]<0,"Loss","No Change")) -> Gain
A7: 45299 | B7: STCK-2105 | C7: Jan | D7: =MONTH(StockData[[#This Row],[DATE]]) -> 1 | E7: 2024 | F7: Q1 | G7: ="Q"&ROUNDUP(StockData[[#This Row],[Month Number]]/3,0) -> Q1 | H7: AXIS BANK | I7: Banking | J7: EQ | K7: 1145 | L7: 1146 | M7: 1118.5 | N7: 1136.95 | O7: 1122 | P7: 1122 | Q7: 1131.56 | R7: 4735538 | S7: 5.3585487e+09 | T7: 140745 | U7: 2091167 | V7: 44.16 | W7: =StockData[[#This Row],[CLOSE]]-StockData[[#This Row],[PREV. CLOSE]] -> -14.95 | X7: =IFERROR((StockData[[#This Row],[CLOSE]]-StockData[[#This Row],[PREV. CLOSE]])/StockData[[#This Row],[PREV. CLOSE]],0) -> -0.013149215 | Y7: =IF(StockData[[#This Row],[Daily Return %]]>0,"Gain",IF(StockData[[#This Row],[Daily Return %]]<0,"Loss","No Change")) -> Loss
A8: 45300 | B8: STCK-2106 | C8: Jan | D8: =MONTH(StockData[[#This Row],[DATE]]) -> 1 | E8: 2024 | F8: Q1 | G8: ="Q"&ROUNDUP(StockData[[#This Row],[Month Number]]/3,0) -> Q1 | H8: AXIS BANK | I8: Banking | J8: EQ | K8: 1128.55 | L8: 1135.55 | M8: 1112.35 | N8: 1122 | O8: 1118.8 | P8: 1116.55 | Q8: 1124.29 | R8: 6359362 | S8: 7.1497649e+09 | T8: 184213 | U8: 3176752 | V8: 49.95 | W8: =StockData[[#This Row],[CLOSE]]-StockData[[#This Row],[PREV. CLOSE]] -> -5.45 | X8: =IFERROR((StockData[[#This Row],[CLOSE]]-StockData[[#This Row],[PREV. CLOSE]])/StockData[[#This Row],[PREV. CLOSE]],0) -> -0.0048573975 | Y8: =IF(StockData[[#This Row],[Daily Return %]]>0,"Gain",IF(StockData[[#This Row],[Daily Return %]]<0,"Loss","No Change")) -> Loss
A9: 45301 | B9: STCK-2107 | C9: Jan | D9: =MONTH(StockData[[#This Row],[DATE]]) -> 1 | E9: 2024 | F9: Q1 | G9: ="Q"&ROUNDUP(StockData[[#This Row],[Month Number]]/3,0) -> Q1 | H9: AXIS BANK | I9: Banking | J9: EQ | K9: 1115.25 | L9: 1116 | M9: 1099.05 | N9: 1116.55 | O9: 1106.95 | P9: 1107 | Q9: 1106.11 | R9: 5934163 | S9: 6.5638414e+09 | T9: 133259 | U9: 3692980 | V9: 62.23 | W9: =StockData[[#This Row],[CLOSE]]-StockData[[#This Row],[PREV. CLOSE]] -> -9.55 | X9: =IFERROR((StockData[[#This Row],[CLOSE]]-StockData[[#This Row],[PREV. CLOSE]])/StockData[[#This Row],[PREV. CLOSE]],0) -> -0.0085531324 | Y9: =IF(StockData[[#This Row],[Daily Return %]]>0,"Gain",IF(StockData[[#This Row],[Daily Return %]]<0,"Loss","No Change")) -> Loss
A10: 45302 | B10: STCK-2108 | C10: Jan | D10: =MONTH(StockData[[#This Row],[DATE]]) -> 1 | E10: 2024 | F10: Q1 | G10: ="Q"&ROUNDUP(StockData[[#This Row],[Month Number]]/3,0) -> Q1 | H10: AXIS BANK | I10: Banking | J10: EQ | K10: 1111.05 | L10: 1127.9 | M10: 1111.05 | N10: 1107 | O10: 1125 | P10: 1125.75 | Q10: 1122.67 | R10: 4683035 | S10: 5.2574898e+09 | T10: 143442 | U10: 3014465 | V10: 64.37 | W10: =StockData[[#This Row],[CLOSE]]-StockData[[#This Row],[PREV. CLOSE]] -> 18.75 | X10: =IFERROR((StockData[[#This Row],[CLOSE]]-StockData[[#This Row],[PREV. CLOSE]])/StockData[[#This Row],[PREV. CLOSE]],0) -> 0.016937669 | Y10: =IF(StockData[[#This Row],[Daily Return %]]>0,"Gain",IF(StockData[[#This Row],[Daily Return %]]<0,"Loss","No Change")) -> Gain
A11: 45303 | B11: STCK-2109 | C11: Jan | D11: =MONTH(StockData[[#This Row],[DATE]]) -> 1 | E11: 2024 | F11: Q1 | G11: ="Q"&ROUNDUP(StockData[[#This Row],[Month Number]]/3,0) -> Q1 | H11: AXIS BANK | I11: Banking | J11: EQ | K11: 1126.35 | L11: 1129.45 | M11: 1118.05 | N11: 1125.75 | O11: 1119.05 | P11: 1120.35 | Q11: 1122.27 | R11: 5616755 | S11: 6.3035287e+09 | T11: 248340 | U11: 3795162 | V11: 67.57 | W11: =StockData[[#This Row],[CLOSE]]-StockData[[#This Row],[PREV. CLOSE]] -> -5.4 | X11: =IFERROR((StockData[[#This Row],[CLOSE]]-StockData[[#This Row],[PREV. CLOSE]])/StockData[[#This Row],[PREV. CLOSE]],0) -> -0.0047968021 | Y11: =IF(StockData[[#This Row],[Daily Return %]]>0,"Gain",IF(StockData[[#This Row],[Daily Return %]]<0,"Loss","No Change")) -> Loss
A12: 45306 | B12: STCK-2110 | C12: Jan | D12: =MONTH(StockData[[#This Row],[DATE]]) -> 1 | E12: 2024 | F12: Q1 | G12: ="Q"&ROUNDUP(StockData[[#This Row],[Month Number]]/3,0) -> Q1 | H12: AXIS BANK | I12: Banking | J12: EQ | K12: 1122 | L12: 1130.45 | M12: 1116.6 | N12: 1120.35 | O12: 1120.5 | P12: 1119.5 | Q12: 1121.23 | R12: 6719079 | S12: 7.5336583e+09 | T12: 248969 | U12: 4049161 | V12: 60.26 | W12: =StockData[[#This Row],[CLOSE]]-StockData[[#This Row],[PREV. CLOSE]] -> -0.85 | X12: =IFERROR((StockData[[#This Row],[CLOSE]]-StockData[[#This Row],[PREV. CLOSE]])/StockData[[#This Row],[PREV. CLOSE]],0) -> -0.00075869148 | Y12: =IF(StockData[[#This Row],[Daily Return %]]>0,"Gain",IF(StockData[[#This Row],[Daily Return %]]<0,"Loss","No Change")) -> Loss
A13: 45307 | B13: STCK-2111 | C13: Jan | D13: =MONTH(StockData[[#This Row],[DATE]]) -> 1 | E13: 2024 | F13: Q1 | G13: ="Q"&ROUNDUP(StockData[[#This Row],[Month Number]]/3,0) -> Q1 | H13: AXIS BANK | I13: Banking | J13: EQ | K13: 1116.65 | L13: 1127.8 | M13: 1115.1 | N13: 1119.5 | O13: 1120.2 | P13: 1119.1 | Q13: 1121.84 | R13: 5229753 | S13: 5.8669226e+09 | T13: 151286 | U13: 3084217 | V13: 58.97 | W13: =StockData[[#This Row],[CLOSE]]-StockData[[#This Row],[PREV. CLOSE]] -> -0.4 | X13: =IFERROR((StockData[[#This Row],[CLOSE]]-StockData[[#This Row],[PREV. CLOSE]])/StockData[[#This Row],[PREV. CLOSE]],0) -> -0.00035730237 | Y13: =IF(StockData[[#This Row],[Daily Return %]]>0,"Gain",IF(StockData[[#This Row],[Daily Return %]]<0,"Loss","No Change")) -> Loss
... A17: 45311 | B17: STCK-2115 | C17: Jan | D17: =MONTH(StockData[[#This Row],[DATE]]) -> 1 | E17: 2024 | F17: Q1 | G17: ="Q"&ROUNDUP(StockData[[#This Row],[Month Number]]/3,0) -> Q1 | H17: AXIS BANK | I17: Banking | J17: EQ | K17: 1121 | L17: 1126.45 | M17: 1102.8 | N17: 1116.55 | O17: 1118.1 | P17: 1121 | Q17: 1115.57 | R17: 5055594 | S17: 5.6398823e+09 | T17: 113131 | U17: 767598 | V17: 15.18 | W17: =StockData[[#This Row],[CLOSE]]-StockData[[#This Row],[PREV. CLOSE]] -> 4.45 | X17: =IFERROR((StockData[[#This Row],[CLOSE]]-StockData[[#This Row],[PREV. CLOSE]])/StockData[[#This Row],[PREV. CLOSE]],0) -> 0.003985491 | Y17: =IF(StockData[[#This Row],[Daily Return %]]>0,"Gain",IF(StockData[[#This Row],[Daily Return %]]<0,"Loss","No Change")) -> Gain
A18: 45314 | B18: STCK-2116 | C18: Jan | D18: =MONTH(StockData[[#This Row],[DATE]]) -> 1 | E18: 2024 | F18: Q1 | G18: ="Q"&ROUNDUP(StockData[[#This Row],[Month Number]]/3,0) -> Q1 | H18: AXIS BANK | I18: Banking | J18: EQ | K18: 1125.9 | L18: 1141.6 | M18: 1078.8 | N18: 1121 | O18: 1082 | P18: 1089.25 | Q18: 1101.48 | R18: 18924087 | S18: 2.0844533e+10 | T18: 298496 | U18: 11125189 | V18: 58.79 | W18: =StockData[[#This Row],[CLOSE]]-StockData[[#This Row],[PREV. CLOSE]] -> -31.75 | X18: =IFERROR((StockData[[#This Row],[CLOSE]]-StockData[[#This Row],[PREV. CLOSE]])/StockData[[#This Row],[PREV. CLOSE]],0) -> -0.028322926 | Y18: =IF(StockData[[#This Row],[Daily Return %]]>0,"Gain",IF(StockData[[#This Row],[Daily Return %]]<0,"Loss","No Change")) -> Loss | AK18: =MATCH(24.8,W2:W9,1) -> 3
A19: 45315 | B19: STCK-2117 | C19: Jan | D19: =MONTH(StockData[[#This Row],[DATE]]) -> 1 | E19: 2024 | F19: Q1 | G19: ="Q"&ROUNDUP(StockData[[#This Row],[Month Number]]/3,0) -> Q1 | H19: AXIS BANK | I19: Banking | J19: EQ | K19: 1034.8 | L19: 1073.2 | M19: 1020.9 | N19: 1089.25 | O19: 1059.6 | P19: 1059.15 | Q19: 1050.55 | R19: 20884046 | S19: 2.1939694e+10 | T19: 381021 | U19: 10475578 | V19: 50.16 | W19: =StockData[[#This Row],[CLOSE]]-StockData[[#This Row],[PREV. CLOSE]] -> -30.1 | X19: =IFERROR((StockData[[#This Row],[CLOSE]]-StockData[[#This Row],[PREV. CLOSE]])/StockData[[#This Row],[PREV. CLOSE]],0) -> -0.027633693 | Y19: =IF(StockData[[#This Row],[Daily Return %]]>0,"Gain",IF(StockData[[#This Row],[Daily Return %]]<0,"Loss","No Change")) -> Loss
A20: 45315 | B20: STCK-2118 | C20: Jan | D20: =MONTH(StockData[[#This Row],[DATE]]) -> 1 | E20: 2024 | F20: Q1 | G20: ="Q"&ROUNDUP(StockData[[#This Row],[Month Number]]/3,0) -> Q1 | H20: AXIS BANK | I20: Banking | J20: EQ | K20: 1034.8 | L20: 1073.2 | M20: 1020.9 | N20: 1089.25 | O20: 1059.6 | P20: 1059.15 | Q20: 1050.55 | R20: 20884046 | S20: 2.1939694e+10 | T20: 381021 | U20: 10475578 | V20: 50.16 | W20: =StockData[[#This Row],[CLOSE]]-StockData[[#This Row],[PREV. CLOSE]] -> -30.1 | X20: =IFERROR((StockData[[#This Row],[CLOSE]]-StockData[[#This Row],[PREV. CLOSE]])/StockData[[#This Row],[PREV. CLOSE]],0) -> -0.027633693 | Y20: =IF(StockData[[#This Row],[Daily Return %]]>0,"Gain",IF(StockData[[#This Row],[Daily Return %]]<0,"Loss","No Change")) -> Loss
A21: 45316 | B21: STCK-2119 | C21: Jan | D21: =MONTH(StockData[[#This Row],[DATE]]) -> 1 | E21: 2024 | F21: Q1 | G21: ="Q"&ROUNDUP(StockData[[#This Row],[Month Number]]/3,0) -> Q1 | H21: AXIS BANK | I21: Banking | J21: EQ | K21: 1058 | L21: 1063.7 | M21: 1025.8 | N21: 1059.15 | O21: 1050.1 | P21: 1042.25 | Q21: 1037.96 | R21: 20835434 | S21: 2.1626312e+10 | T21: 393518 | U21: 12540498 | V21: 60.19 | W21: =StockData[[#This Row],[CLOSE]]-StockData[[#This Row],[PREV. CLOSE]] -> -16.9 | X21: =IFERROR((StockData[[#This Row],[CLOSE]]-StockData[[#This Row],[PREV. CLOSE]])/StockData[[#This Row],[PREV. CLOSE]],0) -> -0.015956191 | Y21: =IF(StockData[[#This Row],[Daily Return %]]>0,"Gain",IF(StockData[[#This Row],[Daily Return %]]<0,"Loss","No Change")) -> Loss
A22: 45320 | B22: STCK-2120 | C22: Jan | D22: =MONTH(StockData[[#This Row],[DATE]]) -> 1 | E22: 2024 | F22: Q1 | G22: ="Q"&ROUNDUP(StockData[[#This Row],[Month Number]]/3,0) -> Q1 | H22: AXIS BANK | I22: Banking | J22: EQ | K22: 1036 | L22: 1068 | M22: 1036 | N22: 1042.25 | O22: 1060.85 | P22: 1061.25 | Q22: 1058.12 | R22: 11188604 | S22: 1.183891e+10 | T22: 205125 | U22: 5918863 | V22: 52.9 | W22: =StockData[[#This Row],[CLOSE]]-StockData[[#This Row],[PREV. CLOSE]] -> 19 | X22: =IFERROR((StockData[[#This Row],[CLOSE]]-StockData[[#This Row],[PREV. CLOSE]])/StockData[[#This Row],[PREV. CLOSE]],0) -> 0.018229791 | Y22: =IF(StockData[[#This Row],[Daily Return %]]>0,"Gain",IF(StockData[[#This Row],[Daily Return %]]<0,"Loss","No Change")) -> Gain
A23: 45321 | B23: STCK-2121 | C23: Jan | D23: =MONTH(StockData[[#This Row],[DATE]]) -> 1 | E23: 2024 | F23: Q1 | G23: ="Q"&ROUNDUP(StockData[[#This Row],[Month Number]]/3,0) -> Q1 | H23: AXIS BANK | I23: Banking | J23: EQ | K23: 1060.05 | L23: 1070.45 | M23: 1050.8 | N23: 1061.25 | O23: 1053.5 | P23: 1054.1 | Q23: 1057.78 | R23: 9426983 | S23: 9.9716989e+09 | T23: 325034 | U23: 4929307 | V23: 52.29 | W23: =StockData[[#This Row],[CLOSE]]-StockData[[#This Row],[PREV. CLOSE]] -> -7.15 | X23: =IFERROR((StockData[[#This Row],[CLOSE]]-StockData[[#This Row],[PREV. CLOSE]])/StockData[[#This Row],[PREV. CLOSE]],0) -> -0.006737338 | Y23: =IF(StockData[[#This Row],[Daily Return %]]>0,"Gain",IF(StockData[[#This Row],[Daily Return %]]<0,"Loss","No Change")) -> Loss
A24: 45322 | B24: STCK-2122 | C24: Jan | D24: =MONTH(StockData[[#This Row],[DATE]]) -> 1 | E24: 2024 | F24: Q1 | G24: ="Q"&ROUNDUP(StockData[[#This Row],[Month Number]]/3,0) -> Q1 | H24: AXIS BANK | I24: Banking | J24: EQ | K24: 1048.2 | L24: 1084.1 | M24: 1042.7 | N24: 1054.1 | O24: 1067.5 | P24: 1067.75 | Q24: 1068.9 | R24: 12600390 | S24: 1.3468519e+10 | T24: 303223 | U24: 6437032 | V24: 51.09 | W24: =StockData[[#This Row],[CLOSE]]-StockData[[#This Row],[PREV. CLOSE]] -> 13.65 | X24: =IFERROR((StockData[[#This Row],[CLOSE]]-StockData[[#This Row],[PREV. CLOSE]])/StockData[[#This Row],[PREV. CLOSE]],0) -> 0.012949436 | Y24: =IF(StockData[[#This Row],[Daily Return %]]>0,"Gain",IF(StockData[[#This Row],[Daily Return %]]<0,"Loss","No Change")) -> Gain
A25: 45323 | B25: STCK-2123 | C25: Feb | D25: =MONTH(StockData[[#This Row],[DATE]]) -> 2 | E25: 2024 | F25: Q1 | G25: ="Q"&ROUNDUP(StockData[[#This Row],[Month Number]]/3,0) -> Q1 | H25: AXIS BANK | I25: Banking | J25: EQ | K25: 1072.65 | L25: 1087.65 | M25: 1056.8 | N25: 1067.75 | O25: 1083.45 | P25: 1084.25 | Q25: 1073.44 | R25: 9756682 | S25: 1.0473227e+10 | T25: 213721 | U25: 5825259 | V25: 59.71 | W25: =StockData[[#This Row],[CLOSE]]-StockData[[#This Row],[PREV. CLOSE]] -> 16.5 | X25: =IFERROR((StockData[[#This Row],[CLOSE]]-StockData[[#This Row],[PREV. CLOSE]])/StockData[[#This Row],[PREV. CLOSE]],0) -> 0.015453055 | Y25: =IF(StockData[[#This Row],[Daily Return %]]>0,"Gain",IF(StockData[[#This Row],[Daily Return %]]<0,"Loss","No Change")) -> Gain
A26: 45324 | B26: STCK-2124 | C26: Feb | D26: =MONTH(StockData[[#This Row],[DATE]]) -> 2 | E26: 2024 | F26: Q1 | G26: ="Q"&ROUNDUP(StockData[[#This Row],[Month Number]]/3,0) -> Q1 | H26: AXIS BANK | I26: Banking | J26: EQ | K26: 1088.05 | L26: 1096.2 | M26: 1065 | N26: 1084.25 | O26: 1067.7 | P26: 1067.05 | Q26: 1078.73 | R26: 8667415 | S26: 9.3497783e+09 | T26: 262152 | U26: 4229192 | V26: 48.79 | W26: =StockData[[#This Row],[CLOSE]]-StockData[[#This Row],[PREV. CLOSE]] -> -17.2 | X26: =IFERROR((StockData[[#This Row],[CLOSE]]-StockData[[#This Row],[PREV. CLOSE]])/StockData[[#This Row],[PREV. CLOSE]],0) -> -0.0158635 | Y26: =IF(StockData[[#This Row],[Daily Return %]]>0,"Gain",IF(StockData[[#This Row],[Daily Return %]]<0,"Loss","No Change")) -> Loss
A27: 45327 | B27: STCK-2125 | C27: Feb | D27: =MONTH(StockData[[#This Row],[DATE]]) -> 2 | E27: 2024 | F27: Q1 | G27: ="Q"&ROUNDUP(StockData[[#This Row],[Month Number]]/3,0) -> Q1 | H27: AXIS BANK | I27: Banking | J27: EQ | K27: 1067.05 | L27: 1079.5 | M27: 1058 | N27: 1067.05 | O27: 1059.2 | P27: 1061.5 | Q27: 1068.12 | R27: 12569454 | S27: 1.3425687e+10 | T27: 267496 | U27: 6255483 | V27: 49.77 | W27: =StockData[[#This Row],[CLOSE]]-StockData[[#This Row],[PREV. CLOSE]] -> -5.55 | X27: =IFERROR((StockData[[#This Row],[CLOSE]]-StockData[[#This Row],[PREV. CLOSE]])/StockData[[#This Row],[PREV. CLOSE]],0) -> -0.0052012558 | Y27: =IF(StockData[[#This Row],[Daily Return %]]>0,"Gain",IF(StockData[[#This Row],[Daily Return %]]<0,"Loss","No Change")) -> Loss
A28: 45328 | B28: STCK-2126 | C28: Feb | D28: =MONTH(StockData[[#This Row],[DATE]]) -> 2 | E28: 2024 | F28: Q1 | G28: ="Q"&ROUNDUP(StockData[[#This Row],[Month Number]]/3,0) -> Q1 | H28: AXIS BANK | I28: Banking | J28: EQ | K28: 1061.55 | L28: 1065.1 | M28: 1048.2 | N28: 1061.5 | O28: 1053 | P28: 1050.05 | Q28: 1054.5 | R28: 8011171 | S28: 8.4477599e+09 | T28: 200742 | U28: 4575694 | V28: 57.12 | W28: =StockData[[#This Row],[CLOSE]]-StockData[[#This Row],[PREV. CLOSE]] -> -11.45 | X28: =IFERROR((StockData[[#This Row],[CLOSE]]-StockData[[#This Row],[PREV. CLOSE]])/StockData[[#This Row],[PREV. CLOSE]],0) -> -0.010786623 | Y28: =IF(StockData[[#This Row],[Daily Return %]]>0,"Gain",IF(StockData[[#This Row],[Daily Return %]]<0,"Loss","No Change")) -> Loss
A29: 45329 | B29: STCK-2127 | C29: Feb | D29: =MONTH(StockData[[#This Row],[DATE]]) -> 2 | E29: 2024 | F29: Q1 | G29: ="Q"&ROUNDUP(StockData[[#This Row],[Month Number]]/3,0) -> Q1 | H29: AXIS BANK | I29: Banking | J29: EQ | K29: 1061.05 | L29: 1073.7 | M29: 1057.5 | N29: 1050.05 | O29: 1072 | P29: 1069.1 | Q29: 1067.49 | R29: 7281793 | S29: 7.7732075e+09 | T29: 218920 | U29: 3122307 | V29: 42.88 | W29: =StockData[[#This Row],[CLOSE]]-StockData[[#This Row],[PREV. CLOSE]] -> 19.05 | X29: =IFERROR((StockData[[#This Row],[CLOSE]]-StockData[[#This Row],[PREV. CLOSE]])/StockData[[#This Row],[PREV. CLOSE]],0) -> 0.018141993 | Y29: =IF(StockData[[#This Row],[Daily Return %]]>0,"Gain",IF(StockData[[#This Row],[Daily Return %]]<0,"Loss","No Change")) -> Gain
A30: 45330 | B30: STCK-2128 | C30: Feb | D30: =MONTH(StockData[[#This Row],[DATE]]) -> 2 | E30: 2024 | F30: Q1 | G30: ="Q"&ROUNDUP(StockData[[#This Row],[Month Number]]/3,0) -> Q1 | H30: AXIS BANK | I30: Banking | J30: EQ | K30: 1072 | L30: 1075.6 | M30: 1031.65 | N30: 1069.1 | O30: 1036.9 | P30: 1035.9 | Q30: 1043.39 | R30: 9869141 | S30: 1.0297387e+10 | T30: 272590 | U30: 5452343 | V30: 55.25 | W30: =StockData[[#This Row],[CLOSE]]-StockData[[#This Row],[PREV. CLOSE]] -> -33.2 | X30: =IFERROR((StockData[[#This Row],[CLOSE]]-StockData[[#This Row],[PREV. CLOSE]])/StockData[[#This Row],[PREV. CLOSE]],0) -> -0.031054158 | Y30: =IF(StockData[[#This Row],[Daily Return %]]>0,"Gain",IF(StockData[[#This Row],[Daily Return %]]<0,"Loss","No Change")) -> Loss
... A6046: 46022 | B6046: STCK-8144 | C6046: Dec | D6046: =MONTH(StockData[[#This Row],[DATE]]) -> 12 | E6046: 2025 | F6046: Q4 | G6046: ="Q"&ROUNDUP(StockData[[#This Row],[Month Number]]/3,0) -> Q4 | H6046: MARUTI SUZUKI | I6046: Automobile | J6046: EQ | K6046: 16581 | L6046: 16776 | M6046: 16581 | N6046: 16647 | O6046: 16688 | P6046: 16697 | Q6046: 16682.77 | R6046: 314427 | S6046: 5245513521 | T6046: 65813 | U6046: 195953 | V6046: 62.32 | W6046: =StockData[[#This Row],[CLOSE]]-StockData[[#This Row],[PREV. CLOSE]] -> 50 | X6046: =IFERROR((StockData[[#This Row],[CLOSE]]-StockData[[#This Row],[PREV. CLOSE]])/StockData[[#This Row],[PREV. CLOSE]],0) -> 0.0030035442 | Y6046: =IF(StockData[[#This Row],[Daily Return %]]>0,"Gain",IF(StockData[[#This Row],[Daily Return %]]<0,"Loss","No Change")) -> Gain

Sheet Summary KPI
A1: Company | B1: Avg Return% | C1: Avg Closing Price | D1: Avg Daily Change
A2: AXIS BANK | B2: =AVERAGEIF(StockData[Stocks],'Summary KPI'!A2,StockData[Daily Return %]) -> 0.00044081221 | C2: =AVERAGEIF(StockData[Stocks],'Summary KPI'!A2,StockData[CLOSE]) -> 1141.804 | D2: =AVERAGEIF(StockData[Stocks],'Summary KPI'!A2,StockData[Daily Price Change]) -> 0.39150198
A3: HDFC BANK | B3: =AVERAGEIF(StockData[Stocks],'Summary KPI'!A3,StockData[Daily Return %]) -> -0.0006203332 | C3: =AVERAGEIF(StockData[Stocks],'Summary KPI'!A3,StockData[CLOSE]) -> 1576.4542 | D3: =AVERAGEIF(StockData[Stocks],'Summary KPI'!A3,StockData[Daily Price Change]) -> -1.4157791
A4: ICICI BANK | B4: =AVERAGEIF(StockData[Stocks],'Summary KPI'!A4,StockData[Daily Return %]) -> 0.00069202059 | C4: =AVERAGEIF(StockData[Stocks],'Summary KPI'!A4,StockData[CLOSE]) -> 1269.1991 | D4: =AVERAGEIF(StockData[Stocks],'Summary KPI'!A4,StockData[Daily Price Change]) -> 0.72693069
A5: TCS | B5: =AVERAGEIF(StockData[Stocks],'Summary KPI'!A5,StockData[Daily Return %]) -> -0.00028914721 | C5: =AVERAGEIF(StockData[Stocks],'Summary KPI'!A5,StockData[CLOSE]) -> 3737.6982 | D5: =AVERAGEIF(StockData[Stocks],'Summary KPI'!A5,StockData[Daily Price Change]) -> -1.2513944
A6: WIPRO | B6: =AVERAGEIF(StockData[Stocks],'Summary KPI'!A6,StockData[Daily Return %]) -> -0.00045602129 | C6: =AVERAGEIF(StockData[Stocks],'Summary KPI'!A6,StockData[CLOSE]) -> 373.41528 | D6: =AVERAGEIF(StockData[Stocks],'Summary KPI'!A6,StockData[Daily Price Change]) -> -0.35749515
A7: HCL | B7: =AVERAGEIF(StockData[Stocks],'Summary KPI'!A7,StockData[Daily Return %]) -> 0.00042042141 | C7: =AVERAGEIF(StockData[Stocks],'Summary KPI'!A7,StockData[CLOSE]) -> 1615.6932 | D7: =AVERAGEIF(StockData[Stocks],'Summary KPI'!A7,StockData[Daily Price Change]) -> 0.46422925
A8: MARICO | B8: =AVERAGEIF(StockData[Stocks],'Summary KPI'!A8,StockData[Daily Return %]) -> 0.00073446663 | C8: =AVERAGEIF(StockData[Stocks],'Summary KPI'!A8,StockData[CLOSE]) -> 649.77259 | D8: =AVERAGEIF(StockData[Stocks],'Summary KPI'!A8,StockData[Daily Price Change]) -> 0.40582329
A9: ITC | B9: =AVERAGEIF(StockData[Stocks],'Summary KPI'!A9,StockData[Daily Return %]) -> -0.00025251946 | C9: =AVERAGEIF(StockData[Stocks],'Summary KPI'!A9,StockData[CLOSE]) -> 437.44851 | D9: =AVERAGEIF(StockData[Stocks],'Summary KPI'!A9,StockData[Daily Price Change]) -> -0.13605578
A10: NESTLE | B10: =AVERAGEIF(StockData[Stocks],'Summary KPI'!A10,StockData[Daily Return %]) -> -0.0026948569 | C10: =AVERAGEIF(StockData[Stocks],'Summary KPI'!A10,StockData[CLOSE]) -> 2375.4715 | D10: =AVERAGEIF(StockData[Stocks],'Summary KPI'!A10,StockData[Daily Price Change]) -> -50.4686
A11: MAHINDRA & MAHINDRA | B11: =AVERAGEIF(StockData[Stocks],'Summary KPI'!A11,StockData[Daily Return %]) -> 0.0016892657 | C11: =AVERAGEIF(StockData[Stocks],'Summary KPI'!A11,StockData[CLOSE]) -> 2851.8031 | D11: =AVERAGEIF(StockData[Stocks],'Summary KPI'!A11,StockData[Daily Price Change]) -> 3.8614314
A12: BAJAJ AUTO | B12: =AVERAGEIF(StockData[Stocks],'Summary KPI'!A12,StockData[Daily Return %]) -> 0.00068884801 | C12: =AVERAGEIF(StockData[Stocks],'Summary KPI'!A12,StockData[CLOSE]) -> 8948.149 | D12: =AVERAGEIF(StockData[Stocks],'Summary KPI'!A12,StockData[Daily Price Change]) -> 4.4462151
A13: MARUTI SUZUKI | B13: =AVERAGEIF(StockData[Stocks],'Summary KPI'!A13,StockData[Daily Return %]) -> 0.0010488874 | C13: =AVERAGEIF(StockData[Stocks],'Summary KPI'!A13,StockData[CLOSE]) -> 12726.104 | D13: =AVERAGEIF(StockData[Stocks],'Summary KPI'!A13,StockData[Daily Price Change]) -> 12.662625
A15: Trading Activity
A16: Company | B16: Total Volume | C16: Total Trading Value | D16: Positive Trading Days | E16: Total Trading Days | F16: Positive Day%
A17: AXIS BANK | B17: =SUMIFS(StockData[VOLUME],StockData[Stocks],'Summary KPI'!A17) -> 4263411107 | C17: =SUMIFS(StockData[VALUE],StockData[Stocks],'Summary KPI'!A17) -> 4.8355276e+12 | D17: =COUNTIFS(StockData[Stocks],'Summary KPI'!A17,StockData[Daily Return %],">0") -> 252 | E17: =COUNTIF(StockData[Stocks],'Summary KPI'!A17) -> 506 | F17: =D17/E17 -> 0.49802372
A18: HDFC BANK | B18: =SUMIFS(StockData[VOLUME],StockData[Stocks],'Summary KPI'!A18) -> 8869862987 | C18: =SUMIFS(StockData[VALUE],StockData[Stocks],'Summary KPI'!A18) -> 1.3537171e+13 | D18: =COUNTIFS(StockData[Stocks],'Summary KPI'!A18,StockData[Daily Return %],">0") -> 261 | E18: =COUNTIF(StockData[Stocks],'Summary KPI'!A18) -> 507 | F18: =D18/E18 -> 0.5147929
A19: ICICI BANK | B19: =SUMIFS(StockData[VOLUME],StockData[Stocks],'Summary KPI'!A19) -> 6460496414 | C19: =SUMIFS(StockData[VALUE],StockData[Stocks],'Summary KPI'!A19) -> 8.0452571e+12 | D19: =COUNTIFS(StockData[Stocks],'Summary KPI'!A19,StockData[Daily Return %],">0") -> 264 | E19: =COUNTIF(StockData[Stocks],'Summary KPI'!A19) -> 505 | F19: =D19/E19 -> 0.52277228
A20: TCS | B20: =SUMIFS(StockData[VOLUME],StockData[Stocks],'Summary KPI'!A20) -> 1281051981 | C20: =SUMIFS(StockData[VALUE],StockData[Stocks],'Summary KPI'!A20) -> 4.7323517e+12 | D20: =COUNTIFS(StockData[Stocks],'Summary KPI'!A20,StockData[Daily Return %],">0") -> 229 | E20: =COUNTIF(StockData[Stocks],'Summary KPI'!A20) -> 502 | F20: =D20/E20 -> 0.4561753
A21: WIPRO | B21: =SUMIFS(StockData[VOLUME],StockData[Stocks],'Summary KPI'!A21) -> 4829675815 | C21: =SUMIFS(StockData[VALUE],StockData[Stocks],'Summary KPI'!A21) -> 1.7450955e+12 | D21: =COUNTIFS(StockData[Stocks],'Summary KPI'!A21,StockData[Daily Return %],">0") -> 260 | E21: =COUNTIF(StockData[Stocks],'Summary KPI'!A21) -> 515 | F21: =D21/E21 -> 0.50485437
A22: HCL | B22: =SUMIFS(StockData[VOLUME],StockData[Stocks],'Summary KPI'!A22) -> 1511148333 | C22: =SUMIFS(StockData[VALUE],StockData[Stocks],'Summary KPI'!A22) -> 2.4174228e+12 | D22: =COUNTIFS(StockData[Stocks],'Summary KPI'!A22,StockData[Daily Return %],">0") -> 252 | E22: =COUNTIF(StockData[Stocks],'Summary KPI'!A22) -> 506 | F22: =D22/E22 -> 0.49802372
A23: MARICO | B23: =SUMIFS(StockData[VOLUME],StockData[Stocks],'Summary KPI'!A23) -> 1100036803 | C23: =SUMIFS(StockData[VALUE],StockData[Stocks],'Summary KPI'!A23) -> 7.1726252e+11 | D23: =COUNTIFS(StockData[Stocks],'Summary KPI'!A23,StockData[Daily Return %],">0") -> 246 | E23: =COUNTIF(StockData[Stocks],'Summary KPI'!A23) -> 498 | F23: =D23/E23 -> 0.4939759
A24: ITC | B24: =SUMIFS(StockData[VOLUME],StockData[Stocks],'Summary KPI'!A24) -> 7599517229 | C24: =SUMIFS(StockData[VALUE],StockData[Stocks],'Summary KPI'!A24) -> 3.31118e+12 | D24: =COUNTIFS(StockData[Stocks],'Summary KPI'!A24,StockData[Daily Return %],">0") -> 234 | E24: =COUNTIF(StockData[Stocks],'Summary KPI'!A24) -> 502 | F24: =D24/E24 -> 0.46613546
A25: NESTLE | B25: =SUMIFS(StockData[VOLUME],StockData[Stocks],'Summary KPI'!A25) -> 479775682 | C25: =SUMIFS(StockData[VALUE],StockData[Stocks],'Summary KPI'!A25) -> 1.0328015e+12 | D25: =COUNTIFS(StockData[Stocks],'Summary KPI'!A25,StockData[Daily Return %],">0") -> 250 | E25: =COUNTIF(StockData[Stocks],'Summary KPI'!A25) -> 500 | F25: =D25/E25 -> 0.5
A26: MAHINDRA & MAHINDRA | B26: =SUMIFS(StockData[VOLUME],StockData[Stocks],'Summary KPI'!A26) -> 1481547632 | C26: =SUMIFS(StockData[VALUE],StockData[Stocks],'Summary KPI'!A26) -> 4.152676e+12 | D26: =COUNTIFS(StockData[Stocks],'Summary KPI'!A26,StockData[Daily Return %],">0") -> 266 | E26: =COUNTIF(StockData[Stocks],'Summary KPI'!A26) -> 503 | F26: =D26/E26 -> 0.52882704
A27: BAJAJ AUTO | B27: =SUMIFS(StockData[VOLUME],StockData[Stocks],'Summary KPI'!A27) -> 225615685 | C27: =SUMIFS(StockData[VALUE],StockData[Stocks],'Summary KPI'!A27) -> 2.0277044e+12 | D27: =COUNTIFS(StockData[Stocks],'Summary KPI'!A27,StockData[Daily Return %],">0") -> 268 | E27: =COUNTIF(StockData[Stocks],'Summary KPI'!A27) -> 502 | F27: =D27/E27 -> 0.53386454
A28: MARUTI SUZUKI | B28: =SUMIFS(StockData[VOLUME],StockData[Stocks],'Summary KPI'!A28) -> 237168796 | C28: =SUMIFS(StockData[VALUE],StockData[Stocks],'Summary KPI'!A28) -> 2.9890274e+12 | D28: =COUNTIFS(StockData[Stocks],'Summary KPI'!A28,StockData[Daily Return %],">0") -> 244 | E28: =COUNTIF(StockData[Stocks],'Summary KPI'!A28) -> 499 | F28: =D28/E28 -> 0.48897796
A31: Company | B31: Gain | C31: Loss | D31: No Change
A32: AXIS BANK | B32: =COUNTIFS(StockData[Stocks],'Summary KPI'!A32,StockData[Gain or Loss],"Gain") -> 252 | C32: =COUNTIFS(StockData[Stocks],'Summary KPI'!$A32,StockData[Gain or Loss],'Summary KPI'!$C$31) -> 254 | D32: =COUNTIFS(StockData[Stocks],'Summary KPI'!A32,StockData[Gain or Loss],'Summary KPI'!$D$31) -> 0
A33: HDFC BANK | B33: =COUNTIFS(StockData[Stocks],'Summary KPI'!A33,StockData[Gain or Loss],"Gain") -> 261 | C33: =COUNTIFS(StockData[Stocks],'Summary KPI'!A33,StockData[Gain or Loss],'Summary KPI'!$C$31) -> 244 | D33: =COUNTIFS(StockData[Stocks],'Summary KPI'!A33,StockData[Gain or Loss],'Summary KPI'!$D$31) -> 2
A34: ICICI BANK | B34: =COUNTIFS(StockData[Stocks],'Summary KPI'!A34,StockData[Gain or Loss],"Gain") -> 264 | C34: =COUNTIFS(StockData[Stocks],'Summary KPI'!A34,StockData[Gain or Loss],'Summary KPI'!$C$31) -> 241 | D34: =COUNTIFS(StockData[Stocks],'Summary KPI'!A34,StockData[Gain or Loss],'Summary KPI'!$D$31) -> 0
A35: TCS | B35: =COUNTIFS(StockData[Stocks],'Summary KPI'!A35,StockData[Gain or Loss],"Gain") -> 229 | C35: =COUNTIFS(StockData[Stocks],'Summary KPI'!A35,StockData[Gain or Loss],'Summary KPI'!$C$31) -> 273 | D35: =COUNTIFS(StockData[Stocks],'Summary KPI'!A35,StockData[Gain or Loss],'Summary KPI'!$D$31) -> 0
A36: WIPRO | B36: =COUNTIFS(StockData[Stocks],'Summary KPI'!A36,StockData[Gain or Loss],"Gain") -> 260 | C36: =COUNTIFS(StockData[Stocks],'Summary KPI'!A36,StockData[Gain or Loss],'Summary KPI'!$C$31) -> 252 | D36: =COUNTIFS(StockData[Stocks],'Summary KPI'!A36,StockData[Gain or Loss],'Summary KPI'!$D$31) -> 3
A37: HCL | B37: =COUNTIFS(StockData[Stocks],'Summary KPI'!A37,StockData[Gain or Loss],"Gain") -> 252 | C37: =COUNTIFS(StockData[Stocks],'Summary KPI'!A37,StockData[Gain or Loss],'Summary KPI'!$C$31) -> 252 | D37: =COUNTIFS(StockData[Stocks],'Summary KPI'!A37,StockData[Gain or Loss],'Summary KPI'!$D$31) -> 2
A38: MARICO | B38: =COUNTIFS(StockData[Stocks],'Summary KPI'!A38,StockData[Gain or Loss],"Gain") -> 246 | C38: =COUNTIFS(StockData[Stocks],'Summary KPI'!A38,StockData[Gain or Loss],'Summary KPI'!$C$31) -> 251 | D38: =COUNTIFS(StockData[Stocks],'Summary KPI'!A38,StockData[Gain or Loss],'Summary KPI'!$D$31) -> 1
A39: ITC | B39: =COUNTIFS(StockData[Stocks],'Summary KPI'!A39,StockData[Gain or Loss],"Gain") -> 234 | C39: =COUNTIFS(StockData[Stocks],'Summary KPI'!A39,StockData[Gain or Loss],'Summary KPI'!$C$31) -> 265 | D39: =COUNTIFS(StockData[Stocks],'Summary KPI'!A39,StockData[Gain or Loss],'Summary KPI'!$D$31) -> 3
A40: NESTLE | B40: =COUNTIFS(StockData[Stocks],'Summary KPI'!A40,StockData[Gain or Loss],"Gain") -> 250 | C40: =COUNTIFS(StockData[Stocks],'Summary KPI'!A40,StockData[Gain or Loss],'Summary KPI'!$C$31) -> 250 | D40: =COUNTIFS(StockData[Stocks],'Summary KPI'!A40,StockData[Gain or Loss],'Summary KPI'!$D$31) -> 0
A41: MAHINDRA & MAHINDRA | B41: =COUNTIFS(StockData[Stocks],'Summary KPI'!A41,StockData[Gain or Loss],"Gain") -> 266 | C41: =COUNTIFS(StockData[Stocks],'Summary KPI'!A41,StockData[Gain or Loss],'Summary KPI'!$C$31) -> 237 | D41: =COUNTIFS(StockData[Stocks],'Summary KPI'!A41,StockData[Gain or Loss],'Summary KPI'!$D$31) -> 0
A42: BAJAJ AUTO | B42: =COUNTIFS(StockData[Stocks],'Summary KPI'!A42,StockData[Gain or Loss],"Gain") -> 268 | C42: =COUNTIFS(StockData[Stocks],'Summary KPI'!A42,StockData[Gain or Loss],'Summary KPI'!$C$31) -> 234 | D42: =COUNTIFS(StockData[Stocks],'Summary KPI'!A42,StockData[Gain or Loss],'Summary KPI'!$D$31) -> 0
A43: MARUTI SUZUKI | B43: =COUNTIFS(StockData[Stocks],'Summary KPI'!A43,StockData[Gain or Loss],"Gain") -> 244 | C43: =COUNTIFS(StockData[Stocks],'Summary KPI'!A43,StockData[Gain or Loss],'Summary KPI'!$C$31) -> 255 | D43: =COUNTIFS(StockData[Stocks],'Summary KPI'!A43,StockData[Gain or Loss],'Summary KPI'!$D$31) -> 0
...

Sheet Pivot
A1: company performance
A3: Row Labels | B3: Average of Daily Return %
A4: AXIS BANK | B4: 0.00044081221
A5: BAJAJ AUTO | B5: 0.00068884801
A6: HCL | B6: 0.00042042141
A7: HDFC BANK | B7: -0.0006203332
A8: ICICI BANK | B8: 0.00069202059
A9: ITC | B9: -0.00025251946
A10: MAHINDRA & MAHINDRA | B10: 0.0016892657
A11: MARICO | B11: 0.00073446663
A12: MARUTI SUZUKI | B12: 0.0010488874
A13: NESTLE | B13: -0.0026948569
A14: TCS | B14: -0.00028914721
A15: WIPRO | B15: -0.00045602129
A16: Grand Total | B16: 0.00011599853
A21: Sector Performance
A22: Row Labels | B22: Average of Daily Return %
A23: Automobile | B23: 0.0011428837
A24: Banking | B24: 0.00016996867
A25: FMCG | B25: -0.00073895256
A26: IT | B26: -0.00010982904
A27: Grand Total | B27: 0.00011599853
A31: Row Labels | B31: Sum of VOLUME
A32: HDFC BANK | B32: 8869862987
A33: ITC | B33: 7599517229
A34: ICICI BANK | B34: 6460496414
A35: WIPRO | B35: 4829675815
A36: AXIS BANK | B36: 4263411107
A37: HCL | B37: 1511148333
A38: MAHINDRA & MAHINDRA | B38: 1481547632
A39: TCS | B39: 1281051981
A40: MARICO | B40: 1100036803
A41: NESTLE | B41: 479775682
A42: MARUTI SUZUKI | B42: 237168796
A43: BAJAJ AUTO | B43: 225615685
A44: Grand Total | B44: 38339308464
A52: Gains vs Loss
A53: Count of Gain or Loss | B53: Column Labels
A54: Row Labels | B54: Gain | C54: Loss | D54: No Change | E54: Grand Total
A55: BAJAJ AUTO | B55: 268 | C55: 234 | E55: 502
...

Sheet Dashboard
J1: Stock Market Performance & Analysis
D4: Top Performing Stock | I4: Top Performing Sector | N4: Average Daily Return | S4: Total Trading Volume | X4: Most Active Stock
D5: 🏆 | F5: =_xlfn.XLOOKUP(MAX(Pivot!B4:B15),Pivot!B4:B15,Pivot!A4:A15) -> MAHINDRA & MAHINDRA | I5: 🏅 | K5: =_xlfn.XLOOKUP(MAX(Pivot!B23:B26),Pivot!B23:B26,Pivot!A23:A26) -> Automobile | N5: 📈 | P5: =GETPIVOTDATA("Daily Return %",Pivot!$A$2) -> 0.00011599853 | S5: 💰 | U5: =TEXT(GETPIVOTDATA("VOLUME",Pivot!$A$31)/1000000000,"0.00")&"B" -> 38.34B | X5: ⚡ | Z5: {=_xlfn.LET(_xlpm.names,Pivot!A32:A43,_xlpm.vol,Pivot!B32:B43,_xlfn.XLOOKUP(MAX(_xlfn._xlws.FILTER(_xlpm.vol,_xlpm.names<>"Grand Total")),_xlfn._xlws.FILTER(_xlpm.vol,_xlpm.names<>"Grand Total"),_xlfn._xlws.FILTER(_xlpm.names,_xlpm.names<>"Grand Total")))} -> HDFC BANK
